<?xml version="1.0"?>
<robot name="antworker">
        
  <!-- Colors -->
  <material name="red">
      <color rgba="1.0 0.0 0.0 1"/>
  </material>

  <material name="green">
      <color rgba="0.0 1.0 0.0 1"/>
  </material>

  <material name="blue">
      <color rgba="0.0 0.0 1.0 1"/>
  </material>

  <material name="yellow">
      <color rgba="1.0 1.0 0.0 1"/>
  </material>

  <material name="black">
      <color rgba="0.0 0.0 0.0 1"/>
  </material>

  <material name="white">
      <color rgba="1.0 1.0 1.0 1"/>
  </material>

  <!-- Links and Joints -->
  <!-- ========================= -->

  <!-- Base -->
  <link name="base_link"></link>

  <!-- Chassis -->
  <link name="chassis_link">
    <visual>
      <geometry>
        <mesh filename="package://antworker_description/description/base/meshes/antworker_chassis.dae" scale="1.0 1.0 1.0"/>
      </geometry>
      <material name="white"/>
    </visual>

    <collision>
      <geometry>
        <mesh filename="package://antworker_description/description/base/meshes/antworker_chassis_collision.stl" scale="1.0 1.0 1.0"/>
      </geometry>
    </collision>

    <inertial>
      <mass value="10"/>
      <inertia ixx="0.62216" ixy="0"        ixz="0" 
                             iyy="0.95216"  iyz="0" 
                                            izz="1.37016"/>
    </inertial>
  </link>

  <joint name="base_link_joint" type="fixed">
    <origin rpy="0 0 0" xyz="0 0 0" />
    <parent link="base_link" />
    <child link="chassis_link" />
  </joint>

  <!-- Front Wheel -->
  <link name="front_wheel_link">      
    <visual>
      <origin rpy="0 1.5707 0" xyz="0 0 0"/>
      <geometry>
        <cylinder length="0.75" radius="0.1"/>
      </geometry>
      <material name="red"/>
    </visual>

    <collision>
      <origin rpy="0 1.5707 0" xyz="0 0 0"/>
      <geometry>
        <cylinder length="0.75" radius="0.1"/>
      </geometry>
    </collision>

    <inertial>
    <mass value="10"/>
    <inertia ixx="0.09875"  ixy="0"       ixz="0" 
                            iyy="0.09875" iyz="0" 
                                          izz="0.01"/>
    </inertial>
  </link>

  <joint name="front_wheel_joint" type="continuous">
    <parent link="chassis_link"/>
    <child link="front_wheel_link"/>
    <origin rpy="0 0 0" xyz="0 0.395 -0.420"/>
    <axis rpy="0 0 0" xyz="1 0 0"/>
    <limit effort="10" velocity="2"/>
    <dynamics damping="0.01" friction="0.01"/>
  </joint>

  <!-- Rear Wheel -->
  <link name="rear_wheel_link">      
    <visual>
      <origin rpy="0 1.5707 0" xyz="0 0 0"/>
      <geometry>
        <cylinder length="0.75" radius="0.1"/>
      </geometry>
      <material name="green"/>
    </visual>

    <collision>
      <origin rpy="0 1.5707 0" xyz="0 0 0"/>
      <geometry>
        <cylinder length="0.75" radius="0.1"/>
      </geometry>
    </collision>

    <inertial>
      <mass value="10"/>
      <inertia ixx="0.09875"  ixy="0"       ixz="0" 
                              iyy="0.09875" iyz="0"
                                            izz="0.01"/>
    </inertial>
  </link>

  <joint name="rear_wheel_joint" type="continuous">
    <parent link="chassis_link"/>
    <child link="rear_wheel_link"/>
    <origin rpy="0 0 0" xyz="0 -0.395 -0.420"/>
    <axis rpy="0 0 0" xyz="1 0 0"/>
    <limit effort="10" velocity="2"/>
    <dynamics damping="0.01" friction="0.01"/>
  </joint>


</robot>
