<?xml version="1.0"?>
<robot name="antworker">
        
  <!-- Colors -->
  <material name="red">
      <color rgba="1.0 0.0 0.0 1"/>
  </material>

  <material name="green">
      <color rgba="0.0 1.0 0.0 1"/>
  </material>

  <material name="blue">
      <color rgba="0.0 0.0 1.0 1"/>
  </material>

  <material name="yellow">
      <color rgba="1.0 1.0 0.0 1"/>
  </material>

  <material name="black">
      <color rgba="0.0 0.0 0.0 1"/>
  </material>

  <material name="white">
      <color rgba="1.0 1.0 1.0 1"/>
  </material>

  <!-- Links and Joints -->
  <!-- ========================= -->

  <!-- Chassis -->
  <link name="chassis_link">
    <visual>
      <geometry>
        <mesh filename="package://antworker_description/description/base/meshes/antworker_chassis.dae" scale="1.0 1.0 1.0"/>
      </geometry>
      <material name="white"/>
    </visual>

    <collision>
      <geometry>
        <mesh filename="package://antworker_description/description/base/meshes/antworker_chassis.dae" scale="1.0 1.0 1.0"/>
      </geometry>
    </collision>

    <inertial>
      <mass value="10"/>
      <inertia ixx="0.62216" ixy="0"        ixz="0" 
                             iyy="0.95216"  iyz="0" 
                                            izz="1.37016"/>
    </inertial>
  </link>

  <!-- Base -->
  <link name="base_link"></link>

  <joint name="base_link_joint" type="fixed">
    <origin rpy="0 0 -1.57" xyz="0 0 0" />
    <parent link="chassis_link" />
    <child link="base_link" />
  </joint>

  <!-- Front Wheel -->
  <link name="front_wheel_link">      
    <visual>
      <origin rpy="0 1.5707 0" xyz="0 0 0"/>
      <geometry>
        <cylinder length="0.75" radius="0.1"/>
      </geometry>
      <material name="red"/>
    </visual>

    <collision>
      <origin rpy="0 1.5707 0" xyz="0 0 0"/>
      <geometry>
        <cylinder length="0.75" radius="0.1"/>
      </geometry>
    </collision>

    <inertial>
    <mass value="10"/>
    <inertia ixx="0.09875"  ixy="0"       ixz="0" 
                            iyy="0.09875" iyz="0" 
                                          izz="0.01"/>
    </inertial>
  </link>

  <joint name="front_wheel_joint" type="continuous">
    <parent link="chassis_link"/>
    <child link="front_wheel_link"/>
    <origin rpy="0 0 0" xyz="0 0.395 -0.420"/>
    <axis rpy="0 0 0" xyz="1 0 0"/>
    <limit effort="10" velocity="2"/>
    <dynamics damping="0.01" friction="0.01"/>
  </joint>

  <!-- Rear Wheel -->
  <link name="rear_wheel_link">      
    <visual>
      <origin rpy="0 1.5707 0" xyz="0 0 0"/>
      <geometry>
        <cylinder length="0.75" radius="0.1"/>
      </geometry>
      <material name="green"/>
    </visual>

    <collision>
      <origin rpy="0 1.5707 0" xyz="0 0 0"/>
      <geometry>
        <cylinder length="0.75" radius="0.1"/>
      </geometry>
    </collision>

    <inertial>
      <mass value="10"/>
      <inertia ixx="0.09875"  ixy="0"       ixz="0" 
                              iyy="0.09875" iyz="0"
                                            izz="0.01"/>
    </inertial>
  </link>

  <joint name="rear_wheel_joint" type="continuous">
    <parent link="chassis_link"/>
    <child link="rear_wheel_link"/>
    <origin rpy="0 0 0" xyz="0 -0.395 -0.420"/>
    <axis rpy="0 0 0" xyz="1 0 0"/>
    <limit effort="10" velocity="2"/>
    <dynamics damping="0.01" friction="0.01"/>
  </joint>

  <link name="arm_base_link">
    <inertial>
      <origin xyz="-0.000648 -0.000166 0.084487" rpy="0 0 0" />
      <mass value="1.697" />
      <inertia ixx="0.004622" ixy="9E-06" ixz="6E-05" iyy="0.004495" iyz="9E-06" izz="0.002079" />
    </inertial>
    <visual>
      <origin xyz="0 0 0" rpy="0 0 0" />
      <geometry>
        <mesh filename="package://antworker_description/description/arm/meshes/base_link.STL" />
      </geometry>
      <material name="">
        <color rgba="0.75294 0.75294 0.75294 1" />
      </material>
    </visual>
    <collision>
      <origin xyz="0 0 0" rpy="0 0 0" />
      <geometry>
        <mesh filename="package://antworker_description/description/arm/meshes/base_link.STL" />
      </geometry>
    </collision>
  </link>

  <joint name="arm_base_link_joint" type="fixed">
    <origin rpy="0 0 -1.57" xyz="0.01 0.33 0.13" />
    <parent link="chassis_link" />
    <child link="arm_base_link" />
  </joint>

  <link name="shoulder_link">
    <inertial>
      <origin xyz="-2.3E-05 -0.010364 -0.07336" rpy="0 0 0" />
      <mass value="1.377" />
      <inertia ixx="0.00457" ixy="1E-06" ixz="2E-06" iyy="0.004831" iyz="0.000448" izz="0.001409" />
    </inertial>
    <visual>
      <origin xyz="0 0 0" rpy="0 0 0" />
      <geometry>
        <mesh filename="package://antworker_description/description/arm/meshes/shoulder_link.STL" />
      </geometry>
      <material name="">
        <color rgba="0.75294 0.75294 0.75294 1" />
      </material>
    </visual>
    <collision>
      <origin xyz="0 0 0" rpy="0 0 0" />
      <geometry>
        <mesh filename="package://antworker_description/description/arm/meshes/shoulder_link.STL" />
      </geometry>
    </collision>
  </link>

  <joint name="joint_1" type="continuous">
    <origin xyz="0 0 0.15643" rpy="-3.1416 0.0 0.0" />
    <parent link="arm_base_link" />
    <child link="shoulder_link" />
    <axis xyz="0 0 1" />
    <limit effort="39" velocity="1.3963" />
  </joint>

  

  <link name="bicep_link">
    <inertial>
      <origin xyz="3.5E-05 -0.208207 -0.01889" rpy="0 0 0" />
      <mass value="1.262" />
      <inertia ixx="0.046752" ixy="-9E-06" ixz="0" iyy="0.00085" iyz="-9.8E-05" izz="0.047188" />
    </inertial>
    <visual>
      <origin xyz="0 0 0" rpy="0 0 0" />
      <geometry>
        <mesh filename="package://antworker_description/description/arm/meshes/bicep_link.STL" />
      </geometry>
      <material name="">
        <color rgba="0.75294 0.75294 0.75294 1" />
      </material>
    </visual>
    <collision>
      <origin xyz="0 0 0" rpy="0 0 0" />
      <geometry>
        <mesh filename="package://antworker_description/description/arm/meshes/bicep_link.STL" />
      </geometry>
    </collision>
  </link>
  <joint name="joint_2" type="revolute">
    <origin xyz="0 0.005375 -0.12838" rpy="1.5708 0.0 0.0" />
    <parent link="shoulder_link" />
    <child link="bicep_link" />
    <axis xyz="0 0 1" />
    <limit lower="-2.24" upper="2.24" effort="39" velocity="1.3963" />
  </joint>
  <link name="forearm_link">
    <inertial>
      <origin xyz="1.8E-05 0.076168 -0.01397" rpy="0 0 0" />
      <mass value="0.93" />
      <inertia ixx="0.008292" ixy="-1E-06" ixz="0" iyy="0.000628" iyz="0.000432" izz="0.008464" />
    </inertial>
    <visual>
      <origin xyz="0 0 0" rpy="0 0 0" />
      <geometry>
        <mesh filename="package://antworker_description/description/arm/meshes/forearm_link.STL" />
      </geometry>
      <material name="">
        <color rgba="0.75294 0.75294 0.75294 1" />
      </material>
    </visual>
    <collision>
      <origin xyz="0 0 0" rpy="0 0 0" />
      <geometry>
        <mesh filename="package://antworker_description/description/arm/meshes/forearm_link.STL" />
      </geometry>
    </collision>
  </link>
  <joint name="joint_3" type="revolute">
    <origin xyz="0 -0.41 0" rpy="3.1416 0 0" />
    <parent link="bicep_link" />
    <child link="forearm_link" />
    <axis xyz="0 0 1" />
    <limit lower="-2.57" upper="2.57" effort="39" velocity="1.3963" />
  </joint>
  <link name="spherical_wrist_1_link">
    <inertial>
      <origin xyz="-1E-06 0.008486 -0.062937" rpy="0 0 0" />
      <mass value="0.6781" />
      <inertia ixx="0.001645" ixy="0" ixz="0" iyy="0.001666" iyz="-0.000234" izz="0.000389" />
    </inertial>
    <visual>
      <origin xyz="0 0 0" rpy="0 0 0" />
      <geometry>
        <mesh filename="package://antworker_description/description/arm/meshes/spherical_wrist_1_link.STL" />
      </geometry>
      <material name="">
        <color rgba="0.75294 0.75294 0.75294 1" />
      </material>
    </visual>
    <collision>
      <origin xyz="0 0 0" rpy="0 0 0" />
      <geometry>
        <mesh filename="package://antworker_description/description/arm/meshes/spherical_wrist_1_link.STL" />
      </geometry>
    </collision>
  </link>
  <joint name="joint_4" type="continuous">
    <origin xyz="0 0.20843 -0.006375" rpy="1.5708 0.0 0.0" />
    <parent link="forearm_link" />
    <child link="spherical_wrist_1_link" />
    <axis xyz="0 0 1" />
    <limit effort="9" velocity="1.2218" />
  </joint>
  <link name="spherical_wrist_2_link">
    <inertial>
      <origin xyz="-1E-06 0.046429 -0.008704" rpy="0 0 0" />
      <mass value="0.678" />
      <inertia ixx="0.001685" ixy="0" ixz="0" iyy="0.0004" iyz="0.000255" izz="0.001696" />
    </inertial>
    <visual>
      <origin xyz="0 0 0" rpy="0 0 0" />
      <geometry>
        <mesh filename="package://antworker_description/description/arm/meshes/spherical_wrist_2_link.STL" />
      </geometry>
      <material name="">
        <color rgba="0.75294 0.75294 0.75294 1" />
      </material>
    </visual>
    <collision>
      <origin xyz="0 0 0" rpy="0 0 0" />
      <geometry>
        <mesh filename="package://antworker_description/description/arm/meshes/spherical_wrist_2_link.STL" />
      </geometry>
    </collision>
  </link>
  <joint name="joint_5" type="revolute">
    <origin xyz="0 -0.00017505 -0.10593" rpy="-1.5708 0.0 0.0" />
    <parent link="spherical_wrist_1_link" />
    <child link="spherical_wrist_2_link" />
    <axis xyz="0 0 1" />
    <limit lower="-2.09" upper="2.09" effort="9" velocity="1.2218" />
  </joint>
  <link name="bracelet_link">
    <inertial>
      <origin xyz="0.000281 0.011402 -0.029798" rpy="0 0 0" />
      <mass value="0.5" />
      <inertia ixx="0.000587" ixy="3E-06" ixz="3E-06" iyy="0.000369" iyz="-0.000118" izz="0.000609" />
    </inertial>
    <visual>
      <origin xyz="0 0 0" rpy="0 0 0" />
      <geometry>
        <mesh filename="package://antworker_description/description/arm/meshes/bracelet_with_vision_link.STL" />
      </geometry>
      <material name="">
        <color rgba="0.75294 0.75294 0.75294 1" />
      </material>
    </visual>
    <collision>
      <origin xyz="0 0 0" rpy="0 0 0" />
      <geometry>
        <mesh filename="package://antworker_description/description/arm/meshes/bracelet_with_vision_link.STL" />
      </geometry>
    </collision>
  </link>
  <joint name="joint_6" type="continuous">
    <origin xyz="0 0.10593 -0.00017505" rpy="1.5708 0.0 0.0" />
    <parent link="spherical_wrist_2_link" />
    <child link="bracelet_link" />
    <axis xyz="0 0 1" />
    <limit effort="9" velocity="1.2218" />
  </joint>
  <link name="end_effector_link">
    <inertial>
      <origin xyz="0 0 0" rpy="0 0 0" />
      <mass value="0" />
      <inertia ixx="0" ixy="0" ixz="0" iyy="0" iyz="0" izz="0" />
    </inertial>
  </link>
  <joint name="end_effector" type="fixed">
    <origin xyz="0 0 -0.061525" rpy="3.1416 0 -3.1416" />
    <parent link="bracelet_link" />
    <child link="end_effector_link" />
    <axis xyz="0 0 0" />
  </joint>
  <link name="camera_link" />
  <joint name="camera_module" type="fixed">
    <origin xyz="0 0.05639 -0.00305" rpy="3.14159265358979 3.14159265358979 0" />
    <parent link="end_effector_link" />
    <child  link="camera_link" />
  </joint>
  <link name="camera_depth_frame" />
  <joint name="depth_module" type="fixed">
    <origin xyz="0.0275 0.066 -0.00305" rpy="3.14159265358979 3.14159265358979 0" />
    <parent link="end_effector_link" />
    <child  link="camera_depth_frame" />
  </joint>
  <link name="camera_color_frame" />
  <joint name="color_module" type="fixed">
    <origin xyz="0 0.05639 -0.00305" rpy="3.14159265358979 3.14159265358979 0" />
    <parent link="end_effector_link" />
    <child  link="camera_color_frame" />
  </joint>


</robot>
